Traceback (most recent call last):
  File "/home/etri01/anaconda3/envs/jyvenv/lib/python3.8/site-packages/wandb/sdk/wandb_config.py", line 165, in __getattr__
    return self.__getitem__(key)
  File "/home/etri01/anaconda3/envs/jyvenv/lib/python3.8/site-packages/wandb/sdk/wandb_config.py", line 130, in __getitem__
    return self._items[key]
KeyError: 'parameters'

The above exception was the direct cause of the following exception:

Traceback (most recent call last):
  File "main_train.py", line 28, in train_model
    optimizer_name=config.parameters,
  File "/home/etri01/anaconda3/envs/jyvenv/lib/python3.8/site-packages/wandb/sdk/wandb_config.py", line 167, in __getattr__
    raise AttributeError(
AttributeError: <class 'wandb.sdk.wandb_config.Config'> object has no attribute 'parameters'
